Workbook
Name \0: #N/A
Name \c: #REF!
Name \s: #REF!
Name \T: '[1]Q144A-02'!#REF!
Name ___INT1: INT(FINANZIARIO!DUEPER)
Name ___INT1: INT('FINANZIARIO (2)'!DUEPER)
Name ___INT1: INT([0]!DUEPER)
Name __cap1: #REF!
Name __cap2: #REF!
Name __cap3: #REF!
Name __TOT1: #REF!
Name __TOT10: #REF!
Name __TOT11: #REF!
Name __tot12: #REF!
Name __TOT2: #REF!
Name __TOT3: #REF!
Name __TOT4: #REF!
Name __TOT5: #REF!
Name __TOT6: #REF!
Name __TOT7: #REF!
Name __TOT8: #REF!
Name __TOT9: #REF!
Name _1Excel_BuiltIn_Print_Titles_1_1_1: [2]Riassunto!#REF!
Name _20500: #REF!
Name _21300: #REF!
Name _21400: #REF!
Name _21600: #REF!
Name _21601: #REF!
Name _23400: #REF!
Name _24000: #REF!
Name _25100: #REF!
Name _25200: #REF!
Name _25700: #REF!
Name _26008: #REF!
Name _26300: #REF!
Name _27500: #REF!
Name _cap1: #REF!
Name _cap2: #REF!
Name _cap3: #REF!
Name _INT1: INT(FINANZIARIO!DUEPER)
Name _INT1: INT('FINANZIARIO (2)'!DUEPER)
Name _INT1: INT(DUEPER)
Name _T: [1]Q144A_02!#REF!
Name _Toc328203711_1: #REF!
Name _Toc328276670_1: #REF!
Name _TOT1: #REF!
Name _TOT10: #REF!
Name _TOT11: #REF!
Name _tot12: #REF!
Name _TOT2: #REF!
Name _TOT3: #REF!
Name _TOT4: #REF!
Name _TOT5: #REF!
Name _TOT6: #REF!
Name _TOT7: #REF!
Name _TOT8: #REF!
Name _TOT9: #REF!
Name _WBS2: #REF!
Name a: '[3]Costi singoli'!#REF!
Name A100_INTERVENTIPREL: #REF!

Sheet OFFERTA
A2: Suburban S.r.l. a Socio Unico | F2: Spett.le
A3: P.IVA: 12352270966 | F3: =[37]ANACO!C7 -> VASTINT ITALY s.r.l.
A4: REA: MB - 2656311 | F4: Via A. Manzoni 38
A5: Sede Legale: | F5: 20121 Milano, Italy
A6: CORNATE D'ADDA (MB) - VIA | F6: P.IVA: 08218800962
A7: BERLINGUER 17/A CAP 20872 | F7: C.a. | G7: =[37]ANACO!C8 -> Mr.Marco Mor/Ing. Esposito
A9: Cornate | B9: d'Adda | E9: =ANACO!C6 -> 45908
A11: Ns. Preventivo | E11: =ANACO!C5 -> P1002_25_CON_REV03_P1 E EI ALLUMINIO
A13: Oggetto: | E13: =ANACO!C9 -> FPO SERRAMENTI E RACCORDO - EX STAZIONE SUSA
A15: Immobile:
A17: RingraziandoVi per la fiducia riservataci nell’averci interpellati, Vi inviamo, per il cantiere in oggetto, nostra offerta per quanto di nostra competenza.
A18: L'offerta è stata redatta analizzando la documentazione ricevuta e potrà subire variazioni al ricevimento di documentazione più precisa. Dalla presente offerta risultano esclusi i ponteggi e la gru di cantiere.
A21: OFFERTA
A22: ITEM | B22: CODICE | C22: LARGH | D22: ALT. | E22: DESCRIZIONE | F22: U.M. | G22: Q.TA' | H22: PREZZO | I22: IMPORTO TOTALE
E24: =ANACO!C12 -> SERRAMENTI SERIE F
A25: =ANACO!B13 -> F1 | B25: =ANACO!$C$5 -> P1002_25_CON_REV03_P1 E EI ALLUMINIO | C25: =ANACO!D13 -> 1100 | D25: =ANACO!F13 -> 1970 | E25: =ANACO!C13 -> Serramento in legno doppia anta battente apertura interna e sopraluce curvo con apertura vasistas fissato solidamente ad un controtelaio in profili di legno adeguatamente trattato e isolato. Compreso controtelaio costituito da profili in legno sagomato a L, adeguatamente trattato per evitare formazione di muffe o deformazioni geometriche, ancorato alla struttura principale mediante adeguate zanche annegate nel muro o viti di fissaggio. Vetro: 66.2 COOL-LITE 70-33#2 INDURITI / 20mm (aria-argon 90%) / 55.2 int. RICOTTI Comprese lamiere di raccordo, memebrane e isolanti. | F25: cad. | G25: =ANACO!H13 -> 10 | H25: =ANACO!BS13 -> 4443.0585 | I25: =G25*H25 -> 44430.585
A26: =ANACO!B14 -> F1a | B26: =ANACO!$C$5 -> P1002_25_CON_REV03_P1 E EI ALLUMINIO | C26: =ANACO!D14 -> 1100 | D26: =ANACO!F14 -> 1970 | E26: =ANACO!C14 -> Serramento in legno doppia anta battente apertura interna e sopraluce curvo con apertura vasistas fissato solidamente ad un controtelaio in profili di legno adeguatamente trattato e isolato. Compreso controtelaio costituito da profili in legno sagomato a L, adeguatamente trattato per evitare formazione di muffe o deformazioni geometriche, ancorato alla struttura principale mediante adeguate zanche annegate nel muro o viti di fissaggio. Vetro: 66.2 COOL-LITE 70-33#2 INDURITI / 20mm (aria-argon 90%) / 55.2 int. RICOTTI Comprese lamiere di raccordo, memebrane e isolanti. | F26: cad. | G26: =ANACO!H14 -> 1 | H26: =ANACO!BS14 -> 4443.0585 | I26: =G26*H26 -> 4443.0585
A27: =ANACO!B15 -> F2 | B27: =ANACO!$C$5 -> P1002_25_CON_REV03_P1 E EI ALLUMINIO | C27: =ANACO!D15 -> 1720 | D27: =ANACO!F15 -> 3710 | E27: =ANACO!C15 -> Serramento in legno doppia anta battente apertura interna e sopraluce curvo fisso. Specchiature fisse laterali e superiori, fissato solidamente ad un controtelaio in profili di legno adeguatamente trattato e isolato e persiane a lamelle fisse esterne. Compreso controtelaio costituito da profili in legno sagomato a L, adeguatamente trattato per evitare formazione di muffe o deformazioni geometriche, ancorato alla struttura principale mediante adeguate zanche annegate nel muro o viti di fissaggio. Vetro: 66.2 COOL-LITE 70-33#2 INDURITI / 20mm (aria-argon 90%) / 55.2 int. RICOTTI Comprese lamiere di raccordo, memebrane e isolanti. | F27: cad. | G27: =ANACO!H15 -> 5 | H27: =ANACO!BS15 -> 9861.8457 | I27: =G27*H27 -> 49309.228
A28: =ANACO!B16 -> F3 - EI60 Serramento in acciaio EI60 tipo Secco EBE85 | B28: =ANACO!$C$5 -> P1002_25_CON_REV03_P1 E EI ALLUMINIO | C28: =ANACO!D16 -> 1200 | D28: =ANACO!F16 -> 3000 | E28: =ANACO!C16 -> Serramento in legno fissa, serramento fissato solidamente ad un controtelaio in profili di legno adeguatamente trattato e isolato. Per questo serramento è richiesta una prestazione di resistenza all’incendio pari a EI60. SOSTITUITO CON ALLUMINIO Reynaers ConceptSystem 77-FP EI 60 (CS 77-FPEI60) Compreso controtelaio costituito da profili in legno sagomato a L, adeguatamente trattato per evitare formazione di muffe o deformazioni geometriche, ancorato alla struttura principale mediante adeguate zanche annegate nel muro o viti di fissaggio. Vetro: 66.2 COOL-LITE 70-33#2 / 14mm (aria-argon 90%) / 27 CF60-3. Comprese lamiere di raccordo, memebrane e isolanti. | F28: cad. | G28: =ANACO!H16 -> 3 | H28: =ANACO!BS16 -> 8821.1292 | I28: =G28*H28 -> 26463.388
A29: =ANACO!B17 -> F3a | B29: =ANACO!$C$5 -> P1002_25_CON_REV03_P1 E EI ALLUMINIO | C29: =ANACO!D17 -> 1200 | D29: =ANACO!F17 -> 3000 | E29: =ANACO!C17 -> Porta a doppio battente apertura interno dell’edificio con pushbar esterno e chiudiporta, presenza di sopraluce fisso è presente un ulteriore sopraluce curvo con presenza di lamelle di areazione. Il serramento presente una prestazione EI60 escluso la parte lamellata. SOSTITUITO CON ALLUMINIO Reynaers ConceptSystem 77-FP EI 60 (CS 77-FPEI60) Compreso controtelaio costituito da profili in legno sagomato a L, adeguatamente trattato per evitare formazione di muffe o deformazioni geometriche, ancorato alla struttura principale mediante adeguate zanche annegate nel muro o viti di fissaggio. Vetro: 66.2 COOL-LITE 70-33#2 / 14mm (aria-argon 90%) / 27 CF60-3. Comprese lamiere di raccordo, memebrane e isolanti. | F29: cad. | G29: =ANACO!H17 -> 1 | H29: =ANACO!BS17 -> 6217.2576 | I29: =G29*H29 -> 6217.2576
A30: =ANACO!B18 -> F3b | B30: =ANACO!$C$5 -> P1002_25_CON_REV03_P1 E EI ALLUMINIO | E30: =ANACO!C18 -> Serramento con specchiature vision fisse è presente un ulteriore sopraluce curvo con presenza di lamelle di areazione. Il serramento presenta una prestazione EI60 escluso la parte lamellata.SOSTITUITO CON ALLUMINIO Reynaers ConceptSystem 77-FP EI 60 (CS 77-FPEI60) Compreso controtelaio costituito da profili in legno sagomato a L, adeguatamente trattato per evitare formazione di muffe o deformazioni geometriche, ancorato alla struttura principale mediante adeguate zanche annegate nel muro o viti di fissaggio. Vetro: 66.2 COOL-LITE 70-33#2 / 14mm (aria-argon 90%) / 27 CF60-3. Comprese lamiere di raccordo, memebrane e isolanti. | F30: cad. | G30: =ANACO!H18 -> 2 | H30: =ANACO!BS18 -> 6217.2576 | I30: =G30*H30 -> 12434.515
A31: =ANACO!B19 -> F4a | B31: =ANACO!$C$5 -> P1002_25_CON_REV03_P1 E EI ALLUMINIO | E31: =ANACO!C19 -> Serramento in acciaio con volta circolare apribile a vasistas meccanizzato e automatico specchiatura inferiore con porta a doppio battente apertura esterna, sopraluce rettangolare fisso. SOSTITUITO CON ALLUMINIO Reynaers ConceptSystem 77-FP EI 60 (CS 77-FPEI60) Controtelaio composto da tubi rettangolari ancorato alla struttura principale mediante adeguate zanche annegate nel muro o viti di fissaggio, il telaio deve essere correttamente isolato e zincato per proteggerlo dalla corrosione. Vetro: 66.2 COOL-LITE 70-33#2 / 14mm (aria-argon 90%) / 27 CF60-3. Comprese lamiere di raccordo, memebrane e isolanti. | F31: cad. | G31: =ANACO!H19 -> 1 | H31: =ANACO!BS19 -> 5827.2489 | I31: =G31*H31 -> 5827.2489
A32: =ANACO!B20 -> F4b | B32: =ANACO!$C$5 -> P1002_25_CON_REV03_P1 E EI ALLUMINIO | E32: =ANACO!C20 -> Porta a doppio battente vetrata, apertura doppia anta verso l’esterno, sopraluce fisso. Compreso controtelaio costituito da profili in legno sagomato a L, adeguatamente trattato per evitare formazione di muffe o deformazioni geometriche, ancorato alla struttura principale mediante adeguate zanche annegate nel muro o viti di fissaggio. Vetro: 66.2 COOL-LITE 70-33#2 INDURITI / 20mm (aria-argon 90%) / 55.2 int. RICOTTI Comprese lamiere di raccordo, memebrane e isolanti. | F32: cad. | G32: =ANACO!H20 -> 1 | H32: =ANACO!BS20 -> 8033.6889 | I32: =G32*H32 -> 8033.6889
A33: =ANACO!B21 -> F5a - EI60 Serramento in acciaio EI60 tipo Secco EBE85 | B33: =ANACO!$C$5 -> P1002_25_CON_REV03_P1 E EI ALLUMINIO | E33: =ANACO!C21 -> Porta a doppio battente apertura interno dell’edificio con pushbar esterno e chiudiporta, presenza di sopraluce fisso è presente un ulteriore sopraluce curvo con presenza di lamelle di areazione. Il serramento presente una prestazione EI60 escluso la parte lamellata. SOSTITUITO CON ALLUMINIO Reynaers ConceptSystem 77-FP EI 60 (CS 77-FPEI60) Compreso controtelaio costituito da profili in legno sagomato a L, adeguatamente trattato per evitare formazione di muffe o deformazioni geometriche, ancorato alla struttura principale mediante adeguate zanche annegate nel muro o viti di fissaggio. Vetro: 66.2 COOL-LITE 70-33#2 / 14mm (aria-argon 90%) / 27 CF60-3. Comprese lamiere di raccordo, memebrane e isolanti. | F33: cad. | G33: =ANACO!H21 -> 1 | H33: =ANACO!BS21 -> 20012.035 | I33: =G33*H33 -> 20012.035
A34: =ANACO!B22 -> F5b - EI60 Serramento in acciaio EI60 tipo Secco EBE85 | B34: =ANACO!$C$5 -> P1002_25_CON_REV03_P1 E EI ALLUMINIO | E34: =ANACO!C22 -> Serramento con specchiature vision fisse è presente un ulteriore sopraluce curvo con presenza di lamelle di areazione. Il serramento presenta una prestazione EI60 escluso la parte lamellata.SOSTITUITO CON ALLUMINIO Reynaers ConceptSystem 77-FP EI 60 (CS 77-FPEI60) Compreso controtelaio costituito da profili in legno sagomato a L, adeguatamente trattato per evitare formazione di muffe o deformazioni geometriche, ancorato alla struttura principale mediante adeguate zanche annegate nel muro o viti di fissaggio. Vetro: 66.2 COOL-LITE 70-33#2 / 14mm (aria-argon 90%) / 27 CF60-3. Comprese lamiere di raccordo, memebrane e isolanti. | F34: cad. | G34: =ANACO!H22 -> 1 | H34: =ANACO!BS22 -> 15793.921 | I34: =G34*H34 -> 15793.921
A35: =ANACO!B23 -> F6 | B35: =ANACO!$C$5 -> P1002_25_CON_REV03_P1 E EI ALLUMINIO | E35: =ANACO!C23 -> Serramento portafinestra in legno doppia anta battente apertura interna fissato solidamente ad un controtelaio in profili di legno adeguatamente trattato e isolato. Compreso controtelaio costituito da profili in legno sagomato a L, adeguatamente trattato per evitare formazione di muffe o deformazioni geometriche, ancorato alla struttura principale mediante adeguate zanche annegate nel muro o viti di fissaggio. Vetro: 66.2 COOL-LITE 70-33#2 INDURITI / 20mm (aria-argon 90%) / 55.2 int. RICOTTI Comprese lamiere di raccordo, memebrane e isolanti. | F35: cad. | G35: =ANACO!H23 -> 11 | H35: =ANACO!BS23 -> 6480.5492 | I35: =G35*H35 -> 71286.041
A36: =ANACO!B24 -> F6a | B36: =ANACO!$C$5 -> P1002_25_CON_REV03_P1 E EI ALLUMINIO | E36: =ANACO!C24 -> Serramento portafinestra in legno doppia anta battente apertura interna fissato solidamente ad un controtelaio in profili di legno adeguatamente trattato e isolato. SERRAMENTO A TENUTA FUMI. Compreso controtelaio costituito da profili in legno sagomato a L, adeguatamente trattato per evitare formazione di muffe o deformazioni geometriche, ancorato alla struttura principale mediante adeguate zanche annegate nel muro o viti di fissaggio. Vetro: 66.2 COOL-LITE 70-33#2 INDURITI / 20mm (aria-argon 90%) / 55.2 int. RICOTTI Comprese lamiere di raccordo, memebrane e isolanti. | F36: cad. | G36: =ANACO!H24 -> 3 | H36: =ANACO!BS24 -> 6353.2022 | I36: =G36*H36 -> 19059.607
A37: =ANACO!B25 -> F6b | B37: =ANACO!$C$5 -> P1002_25_CON_REV03_P1 E EI ALLUMINIO | E37: =ANACO!C25 -> Serramento portafinestra in legno doppia anta battente apertura esterna fissato solidamente ad un controtelaio in profili di legno adeguatamente trattato e isolato. SERRAMENTO A TENUTA FUMI. Compreso controtelaio costituito da profili in legno sagomato a L, adeguatamente trattato per evitare formazione di muffe o deformazioni geometriche, ancorato alla struttura principale mediante adeguate zanche annegate nel muro o viti di fissaggio. Vetro: 66.2 COOL-LITE 70-33#2 INDURITI / 20mm (aria-argon 90%) / 55.2 int. RICOTTI Comprese lamiere di raccordo, memebrane e isolanti. | F37: cad. | G37: =ANACO!H25 -> 1 | H37: =ANACO!BS25 -> 6353.2022 | I37: =G37*H37 -> 6353.2022
A38: =ANACO!B26 -> F7 | B38: =ANACO!$C$5 -> P1002_25_CON_REV03_P1 E EI ALLUMINIO | E38: =ANACO!C26 -> Serramento finestra in legno doppia anta battente apertura interna fissato solidamente ad un controtelaio in profili di legno adeguatamente trattato e isolato. Compreso controtelaio costituito da profili in legno sagomato a L, adeguatamente trattato per evitare formazione di muffe o deformazioni geometriche, ancorato alla struttura principale mediante adeguate zanche annegate nel muro o viti di fissaggio. Vetro: 66.2 COOL-LITE 70-33#2 INDURITI / 20mm (aria-argon 90%) / 55.2 int. RICOTTI Comprese lamiere di raccordo, memebrane e isolanti. | F38: cad. | G38: =ANACO!H26 -> 3 | H38: =ANACO!BS26 -> 4250.9382 | I38: =G38*H38 -> 12752.815
A39: =ANACO!B27 -> F7a | B39: =ANACO!$C$5 -> P1002_25_CON_REV03_P1 E EI ALLUMINIO | E39: =ANACO!C27 -> Serramento finestra in legno doppia anta battente apertura interna fissato solidamente ad un controtelaio in profili di legno adeguatamente trattato e isolato. Compreso controtelaio costituito da profili in legno sagomato a L, adeguatamente trattato per evitare formazione di muffe o deformazioni geometriche, ancorato alla struttura principale mediante adeguate zanche annegate nel muro o viti di fissaggio. Vetro: 66.2 COOL-LITE 70-33#2 INDURITI / 20mm (aria-argon 90%) / 55.2 int. RICOTTI Comprese lamiere di raccordo, memebrane e isolanti. | F39: cad. | G39: =ANACO!H27 -> 2 | H39: =ANACO!BS27 -> 4250.9382 | I39: =G39*H39 -> 8501.8764
E40: =ANACO!C28 -> SERRAMENTI SERIE S
A41: =ANACO!B29 -> S1a | B41: =ANACO!$C$5 -> P1002_25_CON_REV03_P1 E EI ALLUMINIO | E41: =ANACO!C29 -> Serramento in acciaio con volta circolare fissa specchiatura inferiore con porta a doppio battente apertura esterna, sopraluce rettangolare fisso e apribile vasistas di ventilazione ad apertura meccanizzata. Controtelaio composto da tubi rettangolari ancorato alla struttura principale mediante adeguate zanche annegate nel muro o viti di fissaggio, il telaio deve essere correttamente isolato e zincato per proteggerlo dalla corrosione. Vetro: 66.2 COOL-LITE 70-33#2 INDURITI / 20mm (aria-argon 90%) / 55.2 int. INDURITI Comprese lamiere di raccordo, memebrane e isolanti. | F41: cad. | G41: =ANACO!H29 -> 1 | H41: =ANACO!BS29 -> 31940.78 | I41: =G41*H41 -> 31940.78
A42: =ANACO!B30 -> S1b | B42: =ANACO!$C$5 -> P1002_25_CON_REV03_P1 E EI ALLUMINIO | E42: =ANACO!C30 -> Serramento in acciaio con volta circolare fissa specchiatura inferiore con porta a doppio battente apertura esterna, sopraluci rettangolari fissi. Controtelaio composto da tubi rettangolari ancorato alla struttura principale mediante adeguate zanche annegate nel muro o viti di fissaggio, il telaio deve essere correttamente isolato e zincato per proteggerlo dalla corrosione. Vetro: 66.2 COOL-LITE 70-33#2 INDURITI / 20mm (aria-argon 90%) / 55.2 int. INDURITI Comprese lamiere di raccordo, memebrane e isolanti. | F42: cad. | G42: =ANACO!H30 -> 2 | H42: =ANACO!BS30 -> 31940.78 | I42: =G42*H42 -> 63881.559
A43: =ANACO!B31 -> S1c | B43: =ANACO!$C$5 -> P1002_25_CON_REV03_P1 E EI ALLUMINIO | E43: =ANACO!C31 -> Serramento in acciaio con volta circolare fissa specchiatura inferiore con porta US a doppio battente apertura esterna con pushbar, sopraluci rettangolari fissi. Controtelaio composto da tubi rettangolari ancorato alla struttura principale mediante adeguate zanche annegate nel muro o viti di fissaggio, il telaio deve essere correttamente isolato e zincato per proteggerlo dalla corrosione. Vetro: 66.2 COOL-LITE 70-33#2 INDURITI / 20mm (aria-argon 90%) / 55.2 int. INDURITI Comprese lamiere di raccordo, memebrane e isolanti. | F43: cad. | G43: =ANACO!H31 -> 1 | H43: =ANACO!BS31 -> 31940.78 | I43: =G43*H43 -> 31940.78
A44: =ANACO!B32 -> S2a | B44: =ANACO!$C$5 -> P1002_25_CON_REV03_P1 E EI ALLUMINIO | E44: =ANACO!C32 -> Serramento in acciaio con volta circolare fissa specchiatura inferiore con vetri fissi, sopraluce rettangolare fisso e apribile vasistas di ventilazione apertura meccanizzata. Controtelaio composto da tubi rettangolari ancorato alla struttura principale mediante adeguate zanche annegate nel muro o viti di fissaggio, il telaio deve essere correttamente isolato e zincato per proteggerlo dalla corrosione. Vetro: 66.2 COOL-LITE 70-33#2 INDURITI / 20mm (aria-argon 90%) / 55.2 int. INDURITI Comprese lamiere di raccordo, memebrane e isolanti. | F44: cad. | G44: =ANACO!H32 -> 3 | H44: =ANACO!BS32 -> 31239.35 | I44: =G44*H44 -> 93718.049
A45: =ANACO!B33 -> S2b | B45: =ANACO!$C$5 -> P1002_25_CON_REV03_P1 E EI ALLUMINIO | E45: =ANACO!C33 -> Serramento in acciaio con volta circolare fissa specchiatura inferiore con vetri fissi, sopraluce rettangolari fissi. Controtelaio composto da tubi rettangolari ancorato alla struttura principale mediante adeguate zanche annegate nel muro o viti di fissaggio, il telaio deve essere correttamente isolato e zincato per proteggerlo dalla corrosione. Vetro: 66.2 COOL-LITE 70-33#2 INDURITI / 20mm (aria-argon 90%) / 55.2 int. INDURITI Comprese lamiere di raccordo, memebrane e isolanti. | F45: cad. | G45: =ANACO!H33 -> 4 | H45: =ANACO!BS33 -> 31239.35 | I45: =G45*H45 -> 124957.4
A46: =ANACO!B34 -> S2c | B46: =ANACO!$C$5 -> P1002_25_CON_REV03_P1 E EI ALLUMINIO | E46: =ANACO!C34 -> Serramento in acciaio con volta circolare fissa specchiatura inferiore con vetri fissi, sopraluce rettangolare fisso e apribile vasistas di ventilazione apertura meccanizzata. Controtelaio composto da tubi rettangolari ancorato alla struttura principale mediante adeguate zanche annegate nel muro o viti di fissaggio, il telaio deve essere correttamente isolato e zincato per proteggerlo dalla corrosione. Vetro: 66.2 COOL-LITE 70-33#2 INDURITI / 20mm (aria-argon 90%) / 55.2 int. INDURITI Comprese lamiere di raccordo, memebrane e isolanti. | F46: cad. | G46: =ANACO!H34 -> 1 | H46: =ANACO!BS34 -> 31239.35 | I46: =G46*H46 -> 31239.35
A47: =ANACO!B35 -> S3 | B47: =ANACO!$C$5 -> P1002_25_CON_REV03_P1 E EI ALLUMINIO | E47: =ANACO!C35 -> Serramento in acciaio con volta circolare fissa, specchiatura inferiore con porta scorrevole ad anta e fissi laterali, sopraluce rettangolare fisso e apribile vasistas di ventilazione apertura meccanizzata. Controtelaio composto da tubi rettangolari ancorato alla struttura principale mediante adeguate zanche annegate nel muro o viti di fissaggio, il telaio deve essere correttamente isolato e zincato per proteggerlo dalla corrosione. Vetro: 66.2 COOL-LITE 70-33#2 INDURITI / 20mm (aria-argon 90%) / 55.2 int. INDURITI Comprese lamiere di raccordo, memebrane e isolanti. | F47: cad. | G47: =ANACO!H35 -> 2 | H47: =ANACO!BS35 -> 36551.15 | I47: =G47*H47 -> 73102.299
A48: =ANACO!B36 -> S4 | B48: =ANACO!$C$5 -> P1002_25_CON_REV03_P1 E EI ALLUMINIO | E48: =ANACO!C36 -> Serramento in acciaio con volta circolare apribile a vasistas specchiatura inferiore con porta a doppio battente apertura esterna, sopraluce rettangolare fisso Controtelaio composto da tubi rettangolari ancorato alla struttura principale mediante adeguate zanche annegate nel muro o viti di fissaggio, il telaio deve essere correttamente isolato e zincato per proteggerlo dalla corrosione. Vetro: 66.2 COOL-LITE 70-33#2 INDURITI / 20mm (aria-argon 90%) / 55.2 int. INDURITI Comprese lamiere di raccordo, memebrane e isolanti. | F48: cad. | G48: =ANACO!H36 -> 2 | H48: =ANACO!BS36 -> 16983.554 | I48: =G48*H48 -> 33967.109
A49: =ANACO!B37 -> S4a - EI60 | B49: =ANACO!$C$5 -> P1002_25_CON_REV03_P1 E EI ALLUMINIO | E49: =ANACO!C37 -> Serramento in acciaio con volta circolare apribile a vasistas meccanizzato e automatico specchiatura inferiore con porta a doppio battente apertura esterna, sopraluce rettangolare fisso. SOSTITUITO CON ALLUMINIO Reynaers ConceptSystem 77-FP EI 60 (CS 77-FPEI60) Controtelaio composto da tubi rettangolari ancorato alla struttura principale mediante adeguate zanche annegate nel muro o viti di fissaggio, il telaio deve essere correttamente isolato e zincato per proteggerlo dalla corrosione. Vetro: 66.2 COOL-LITE 70-33#2 / 14mm (aria-argon 90%) / 27 CF60-3. Comprese lamiere di raccordo, memebrane e isolanti. | F49: cad. | G49: =ANACO!H37 -> 1 | H49: =ANACO!BS37 -> 20724.532 | I49: =G49*H49 -> 20724.532
...

Sheet ANACO
C2: ANALISI COSTO PREVENTIVO | BU2: Comm.
C3: SUBURBAN SRL a Socio Unico ANALISI PREVENTIVA | D3: Dimensioni ESTERNO TELAIO | G3: Mq. | I3: Mq. | BB3: COSTO MATERALE LAVORATO E POSATO CAD: | BC3: COSTO MATERALE LAVORATO E POSATO TOT. | BD3: COSTO MATERALE LAVORATO E POSATO MQ. | BE3: COSTI POST - MATERIALE POSATO | BM3: COSTI INDUSTRIALI DA COSTI MATERIALE | BP3: MOL SU BASE COSTI MATERIALE | BS3: PREZZO CLIENTE CAD. | BT3: PREZZO CLIENTE TOT. | BU3: PREZZO CLIENTE MQ..
B4: Pos. | D4: B | E4: * | F4: H | G4: MQ/Cad. | H4: Qt. | I4: MQ TOTALI | J4: PRODOTTO ACQUISTATO FINITO LEGNO O LEGNO ALLUMINIO | K4: Sc 1 | L4: Sc 2 | M4: Sc 3 | N4: PRODOTTO ACQUISTATO FINITO LEGNO O LEGNO ALLUMINIO Scontato CAD. | O4: PRODOTTO ACQUISTATO FINITO LEGNO O LEGNO ALLUMINIO Scontato TOTALE | P4: ST /LZ - STAFFAME CAD. | Q4: sc 1 | R4: ST /LZ - STAFFAME SCONTATO CAD. | S4: ST /LZ - STAFFAME TOT. | T4: Accessorio Maniglie e Maniglioni Listino CAD. | U4: sc 1 | V4: Accessorio Maniglie e Maniglioni CAD. | W4: Accessorio Maniglie e Maniglioni TOTALE | X4: LA Listino | Y4: Sc 1 | Z4: Sc 2 | AA4: Sc 3 | AB4: LA CAD | AC4: LA TOTALE | AD4: PACCHETTO DI COIBENTAZIONE CAD | AE4: PACCHETTO DI COIBENTAZIONECOIBENTAZIONE TOTALE | AF4: SISTEMA ALLUMINIO E ACCESSORI DI SISTEMA CAD. | AG4: SISTEMA ALLUMINIO E ACCESSORI DI SISTEMA TOTALE | AH4: SISTEMA ACCIAIO E ACCESSORI DI SISTEMA CAD. | AI4: SISTEMA ACCIAIO E ACCESSORI DI SISTEMA TOTALE | AJ4: Trasformazione Acciaio CAD. | AK4: Trasformazione Acciaio TOTALE | AL4: Automatismo CAD. | AM4: Automatismo TOTALE | AN4: Vetro CAD. | AO4: Vetro TOTALE. | AP4: Pannell CAD. | AQ4: Pannell TOTALE | AR4: Controtelaio CAD. | AS4: Controtelaio TOTALE. | AT4: Trasformazione Alluminio CAD. | AU4: Trasformazione Alluminio TOTALE. | AV4: Posa SER e FAC.. CAD | AW4: Posa SER e FAC.. TOTALE | AX4: FW FINITA LIN CAD | AY4: FW FINITA TOTALE | AZ4: NOLO CAD. | BA4: NOLO TOTALE | BE4: Trasporto e Imballo CAD: | BF4: Trasporto e Imballo TOT. | BG4: sviluppo tecnico e PM CAD. | BH4: sviluppo tecnico e PM TOTALE. | BI4: PRESIDIO CANTIERE SITE MNG NOLI CANTIERIZZAZIONE CAD. | BJ4: PRESIDIO CANTIERE SITE MNG NOLI CANTIERIZZAZIONE TOT. | BK4: EXTRA CAD. | BL4: EXTRA TOT. | BM4: % | BN4: EURO | BO4: EURO | BP4: % | BQ4: EURO | BR4: EURO | BV4: Note
B5: COD. | C5: P1002_25_CON_REV03_P1 E EI ALLUMINIO | D5: mm | F5: mm | G5: mq | I5: mq | K5: 1 | L5: 1 | M5: 1 | Q5: 1 | T5: 650 | U5: 1 | X5: 22 | Y5: 1 | Z5: 1 | AA5: 1 | AD5: 15 | AF5: 0 | AH5: =428*0.8 -> 342.4 | AL5: 60 | AN5: 135 | AR5: 35 | AT5: 0 | AV5: 132.5 | AZ5: 360 | BE5: 0.012 | BG5: 0.015 | BI5: 0.005 | BK5: 0.01 | BM5: 0 | BP5: 0.32
B6: DATA | C6: 45908 | P6: 18 | T6: 1930 | AD6: 28 | AH6: =1210*0.8 -> 968 | AN6: 135 | AP6: 0 | AR6: 45 | AT6: 0 | AV6: 23000 | AZ6: 90
B7: CLIENTE RAG.SOCIALE | C7: VASTINT ITALY s.r.l. | P7: 3.9 | AD7: 0 | AH7: 0 | AN7: =AN5*2 -> 270 | AT7: 0 | AV7: 234 | AZ7: =AZ5*AZ6 -> 32400
B8: RIFERIMENTO | C8: Mr.Marco Mor/Ing. Esposito | AH8: 0 | AN8: 595 | AT8: 0 | AV8: 1286 | AZ8: =AZ7/I157*0 -> 0
B9: OGGETTO | C9: FPO SERRAMENTI E RACCORDO - EX STAZIONE SUSA
B11: ITEMS | C11: DESCRIZIONE D'OFFERTA | BN11: CAD. | BO11: TOT. | BQ11: CAD. | BR11: TOT.
C12: SERRAMENTI SERIE F | G12: =(D12*F12)/1000000 -> 0 | I12: =G12*H12 -> 0 | J12: 0 | K12: =J12*$K$5 -> 0 | L12: =K12*$L$5 -> 0 | M12: =L12*$M$5 -> 0 | N12: =M12 -> 0 | O12: =N12*H12 -> 0 | P12: 0 | Q12: =P12*$Q$5 -> 0 | R12: 0 | S12: =R12*H12 -> 0 | T12: 0 | U12: =T12*$U$5 -> 0 | V12: 0 | W12: =V12*H12 -> 0 | X12: 0 | Y12: =X12*$Y$5 -> 0 | Z12: =Y12*$Z$5 -> 0 | AA12: =Z12*$AA$5 -> 0 | AB12: =AA12 -> 0 | AC12: =AB12*H12 -> 0 | AD12: 0 | AE12: =AD12*H12 -> 0 | AF12: 0 | AG12: =AF12*H12 -> 0 | AH12: 0 | AI12: =AH12*H12 -> 0 | AJ12: 0 | AK12: =AJ12*H12 -> 0 | AL12: 0 | AM12: =AL12*H12 -> 0 | AN12: 0 | AO12: =AN12*H12 -> 0 | AP12: 0 | AQ12: =AP12*H12 -> 0 | AR12: 0 | AS12: =AR12*H12 -> 0 | AT12: 0 | AU12: =AT12*H12 -> 0 | AV12: 0 | AW12: =AV12*H12 -> 0 | AX12: 0 | AY12: =AX12*H12 -> 0 | AZ12: 0 | BA12: =AZ12*H12 -> 0 | BB12: =N12+R12+V12+AB12+AD12+AF12+AH12+AJ12+AL12+AN12+AP12+AR12+AT12+AV12+AX12+AZ12 -> 0 | BC12: =O12+S12+W12+AC12+AE12+AG12+AI12+AK12+AM12+AO12+AQ12+AS12+AU12+AW12+AY12+BA12 -> 0 | BD12: =BC12/I12 -> #DIV/0! | BE12: =BB12*$BE$5 -> 0 | BF12: =BC12*$BE$5 -> 0 | BG12: =BB12*$BG$5 -> 0 | BH12: =BC12*$BG$5 -> 0 | BI12: =BB12*$BI$5 -> 0 | BJ12: =BC12*$BI$5 -> 0 | BK12: =BB12*$BK$5 -> 0 | BL12: =BC12*$BK$5 -> 0 | BM12: =$BM$5 -> 0 | BN12: =BB12*BM12 -> 0 | BO12: =BC12*BM$12 -> 0 | BP12: =$BP$5 -> 0.32 | BQ12: =BB12*$BP12 -> 0 | BR12: =BC12*BP12 -> 0 | BS12: =BB12+BE12+BG12+BI12+BK12+BN12+BQ12 -> 0 | BT12: =BC12+BF12+BH12+BJ12+BL12+BO12+BR12 -> 0 | BU12: =BT12/I12 -> #DIV/0!
B13: F1 | C13: Serramento in legno doppia anta battente apertura interna e sopraluce curvo con apertura vasistas fissato solidamente ad un controtelaio in profili di legno adeguatamente trattato e isolato. Compreso controtelaio costituito da profili in legno sagomato a L, adeguatamente trattato per evitare formazione di muffe o deformazioni geometriche, ancorato alla struttura principale mediante adeguate zanche annegate nel muro o viti di fissaggio. Vetro: 66.2 COOL-LITE 70-33#2 INDURITI / 20mm (aria-argon 90%) / 55.2 int. RICOTTI Comprese lamiere di raccordo, memebrane e isolanti. | D13: 1100 | F13: 1970 | G13: =(D13*F13)/1000000 -> 2.167 | H13: 10 | I13: =G13*H13 -> 21.67 | K13: =J13*$K$5 -> 0 | L13: =K13*$L$5 -> 0 | M13: =L13*$M$5 -> 0 | N13: =M13 -> 0 | O13: =N13*H13 -> 0 | P13: 0 | Q13: =P13*$Q$5 -> 0 | R13: 0 | S13: =R13*H13 -> 0 | T13: =$T$5 -> 650 | U13: =T13*$U$5 -> 650 | V13: =U13 -> 650 | W13: =V13*H13 -> 6500 | X13: =($X$5*2*(D13+F13))/1000 -> 135.08 | Y13: =X13*$Y$5 -> 135.08 | Z13: =Y13*$Z$5 -> 135.08 | AA13: =Z13*$AA$5 -> 135.08 | AB13: =AA13 -> 135.08 | AC13: =AB13*H13 -> 1350.8 | AD13: =$AD$5*G13 -> 32.505 | AE13: =AD13*H13 -> 325.05 | AF13: 710 | AG13: =AF13*H13 -> 7100 | AH13: 0 | AI13: =AH13*H13 -> 0 | AJ13: 0 | AK13: =AJ13*H13 -> 0 | AL13: =$AL$5 -> 60 | AM13: =AL13*H13 -> 600 | AN13: =$AN$5*G13 -> 292.545 | AO13: =AN13*H13 -> 2925.45 | AP13: 0 | AQ13: =AP13*H13 -> 0 | AR13: =($AR$5*2*(D13+F13))/1000 -> 214.9 | AS13: =AR13*H13 -> 2149 | AT13: 880 | AU13: =AT13*H13 -> 8800 | AV13: =$AV$5*G13 -> 287.1275 | AW13: =AV13*H13 -> 2871.275 | AX13: 0 | AY13: =AX13*H13 -> 0 | AZ13: =$AZ$8*G13 -> 0 | BA13: =AZ13*H13 -> 0 | BB13: =N13+R13+V13+AB13+AD13+AF13+AH13+AJ13+AL13+AN13+AP13+AR13+AT13+AV13+AX13+AZ13 -> 3262.1575 | BC13: =O13+S13+W13+AC13+AE13+AG13+AI13+AK13+AM13+AO13+AQ13+AS13+AU13+AW13+AY13+BA13 -> 32621.575 | BD13: =BC13/I13 -> 1505.3796 | BE13: =BB13*$BE$5 -> 39.14589 | BF13: =BC13*$BE$5 -> 391.4589 | BG13: =BB13*$BG$5 -> 48.932363 | BH13: =BC13*$BG$5 -> 489.32362 | BI13: =BB13*$BI$5 -> 16.310787 | BJ13: =BC13*$BI$5 -> 163.10788 | BK13: =BB13*$BK$5 -> 32.621575 | BL13: =BC13*$BK$5 -> 326.21575 | BM13: =$BM$5 -> 0 | BN13: =BB13*BM13 -> 0 | BO13: =BC13*BM$12 -> 0 | BP13: =$BP$5 -> 0.32 | BQ13: =BB13*$BP13 -> 1043.8904 | BR13: =BC13*BP13 -> 10438.904 | BS13: =BB13+BE13+BG13+BI13+BK13+BN13+BQ13 -> 4443.0585 | BT13: =BC13+BF13+BH13+BJ13+BL13+BO13+BR13 -> 44430.585 | BU13: =BT13/I13 -> 2050.327
B14: F1a | C14: Serramento in legno doppia anta battente apertura interna e sopraluce curvo con apertura vasistas fissato solidamente ad un controtelaio in profili di legno adeguatamente trattato e isolato. Compreso controtelaio costituito da profili in legno sagomato a L, adeguatamente trattato per evitare formazione di muffe o deformazioni geometriche, ancorato alla struttura principale mediante adeguate zanche annegate nel muro o viti di fissaggio. Vetro: 66.2 COOL-LITE 70-33#2 INDURITI / 20mm (aria-argon 90%) / 55.2 int. RICOTTI Comprese lamiere di raccordo, memebrane e isolanti. | D14: 1100 | F14: 1970 | G14: =(D14*F14)/1000000 -> 2.167 | H14: 1 | I14: =G14*H14 -> 2.167 | K14: =J14*$K$5 -> 0 | L14: =K14*$L$5 -> 0 | M14: =L14*$M$5 -> 0 | N14: =M14 -> 0 | O14: =N14*H14 -> 0 | P14: 0 | Q14: =P14*$Q$5 -> 0 | R14: 0 | S14: =R14*H14 -> 0 | T14: =$T$5 -> 650 | U14: =T14*$U$5 -> 650 | V14: =U14 -> 650 | W14: =V14*H14 -> 650 | X14: =($X$5*2*(D14+F14))/1000 -> 135.08 | Y14: =X14*$Y$5 -> 135.08 | Z14: =Y14*$Z$5 -> 135.08 | AA14: =Z14*$AA$5 -> 135.08 | AB14: =AA14 -> 135.08 | AC14: =AB14*H14 -> 135.08 | AD14: =$AD$5*G14 -> 32.505 | AE14: =AD14*H14 -> 32.505 | AF14: 710 | AG14: =AF14*H14 -> 710 | AH14: 0 | AI14: =AH14*H14 -> 0 | AJ14: 0 | AK14: =AJ14*H14 -> 0 | AL14: =$AL$5 -> 60 | AM14: =AL14*H14 -> 60 | AN14: =$AN$5*G14 -> 292.545 | AO14: =AN14*H14 -> 292.545 | AP14: 0 | AQ14: =AP14*H14 -> 0 | AR14: =($AR$5*2*(D14+F14))/1000 -> 214.9 | AS14: =AR14*H14 -> 214.9 | AT14: 880 | AU14: =AT14*H14 -> 880 | AV14: =$AV$5*G14 -> 287.1275 | AW14: =AV14*H14 -> 287.1275 | AX14: 0 | AY14: =AX14*H14 -> 0 | AZ14: =$AZ$8*G14 -> 0 | BA14: =AZ14*H14 -> 0 | BB14: =N14+R14+V14+AB14+AD14+AF14+AH14+AJ14+AL14+AN14+AP14+AR14+AT14+AV14+AX14+AZ14 -> 3262.1575 | BC14: =O14+S14+W14+AC14+AE14+AG14+AI14+AK14+AM14+AO14+AQ14+AS14+AU14+AW14+AY14+BA14 -> 3262.1575 | BD14: =BC14/I14 -> 1505.3796 | BE14: =BB14*$BE$5 -> 39.14589 | BF14: =BC14*$BE$5 -> 39.14589 | BG14: =BB14*$BG$5 -> 48.932363 | BH14: =BC14*$BG$5 -> 48.932363 | BI14: =BB14*$BI$5 -> 16.310787 | BJ14: =BC14*$BI$5 -> 16.310787 | BK14: =BB14*$BK$5 -> 32.621575 | BL14: =BC14*$BK$5 -> 32.621575 | BM14: =$BM$5 -> 0 | BN14: =BB14*BM14 -> 0 | BO14: =BC14*BM$12 -> 0 | BP14: =$BP$5 -> 0.32 | BQ14: =BB14*$BP14 -> 1043.8904 | BR14: =BC14*BP14 -> 1043.8904 | BS14: =BB14+BE14+BG14+BI14+BK14+BN14+BQ14 -> 4443.0585 | BT14: =BC14+BF14+BH14+BJ14+BL14+BO14+BR14 -> 4443.0585 | BU14: =BT14/I14 -> 2050.327
B15: F2 | C15: Serramento in legno doppia anta battente apertura interna e sopraluce curvo fisso. Specchiature fisse laterali e superiori, fissato solidamente ad un controtelaio in profili di legno adeguatamente trattato e isolato e persiane a lamelle fisse esterne. Compreso controtelaio costituito da profili in legno sagomato a L, adeguatamente trattato per evitare formazione di muffe o deformazioni geometriche, ancorato alla struttura principale mediante adeguate zanche annegate nel muro o viti di fissaggio. Vetro: 66.2 COOL-LITE 70-33#2 INDURITI / 20mm (aria-argon 90%) / 55.2 int. RICOTTI Comprese lamiere di raccordo, memebrane e isolanti. | D15: 1720 | F15: 3710 | G15: =(D15*F15)/1000000 -> 6.3812 | H15: 5 | I15: =G15*H15 -> 31.906 | K15: =J15*$K$5 -> 0 | L15: =K15*$L$5 -> 0 | M15: =L15*$M$5 -> 0 | N15: =M15 -> 0 | O15: =N15*H15 -> 0 | P15: 0 | Q15: =P15*$Q$5 -> 0 | R15: 0 | S15: =R15*H15 -> 0 | T15: =$T$5 -> 650 | U15: =T15*$U$5 -> 650 | V15: =U15 -> 650 | W15: =V15*H15 -> 3250 | X15: =($X$5*2*(D15+F15))/1000 -> 238.92 | Y15: =X15*$Y$5 -> 238.92 | Z15: =Y15*$Z$5 -> 238.92 | AA15: =Z15*$AA$5 -> 238.92 | AB15: =AA15 -> 238.92 | AC15: =AB15*H15 -> 1194.6 | AD15: =$AD$5*G15 -> 95.718 | AE15: =AD15*H15 -> 478.59 | AF15: 1029 | AG15: =AF15*H15 -> 5145 | AH15: 0 | AI15: =AH15*H15 -> 0 | AJ15: 0 | AK15: =AJ15*H15 -> 0 | AL15: =$AL$5 -> 60 | AM15: =AL15*H15 -> 300 | AN15: =$AN$5*G15 -> 861.462 | AO15: =AN15*H15 -> 4307.31 | AP15: 0 | AQ15: =AP15*H15 -> 0 | AR15: =($AR$5*2*(D15+F15))/1000 -> 380.1 | AS15: =AR15*H15 -> 1900.5 | AT15: =15400/5 -> 3080 | AU15: =AT15*H15 -> 15400 | AV15: =$AV$5*G15 -> 845.509 | AW15: =AV15*H15 -> 4227.545 | AX15: 0 | AY15: =AX15*H15 -> 0 | AZ15: =$AZ$8*G15 -> 0 | BA15: =AZ15*H15 -> 0 | BB15: =N15+R15+V15+AB15+AD15+AF15+AH15+AJ15+AL15+AN15+AP15+AR15+AT15+AV15+AX15+AZ15 -> 7240.709 | BC15: =O15+S15+W15+AC15+AE15+AG15+AI15+AK15+AM15+AO15+AQ15+AS15+AU15+AW15+AY15+BA15 -> 36203.545 | BD15: =BC15/I15 -> 1134.6939 | BE15: =BB15*$BE$5 -> 86.888508 | BF15: =BC15*$BE$5 -> 434.44254 | BG15: =BB15*$BG$5 -> 108.61063 | BH15: =BC15*$BG$5 -> 543.05318 | BI15: =BB15*$BI$5 -> 36.203545 | BJ15: =BC15*$BI$5 -> 181.01772 | BK15: =BB15*$BK$5 -> 72.40709 | BL15: =BC15*$BK$5 -> 362.03545 | BM15: =$BM$5 -> 0 | BN15: =BB15*BM15 -> 0 | BO15: =BC15*BM$12 -> 0 | BP15: =$BP$5 -> 0.32 | BQ15: =BB15*$BP15 -> 2317.0269 | BR15: =BC15*BP15 -> 11585.134 | BS15: =BB15+BE15+BG15+BI15+BK15+BN15+BQ15 -> 9861.8457 | BT15: =BC15+BF15+BH15+BJ15+BL15+BO15+BR15 -> 49309.228 | BU15: =BT15/I15 -> 1545.4532
A16: EI | B16: F3 - EI60 Serramento in acciaio EI60 tipo Secco EBE85 | C16: Serramento in legno fissa, serramento fissato solidamente ad un controtelaio in profili di legno adeguatamente trattato e isolato. Per questo serramento è richiesta una prestazione di resistenza all’incendio pari a EI60. SOSTITUITO CON ALLUMINIO Reynaers ConceptSystem 77-FP EI 60 (CS 77-FPEI60) Compreso controtelaio costituito da profili in legno sagomato a L, adeguatamente trattato per evitare formazione di muffe o deformazioni geometriche, ancorato alla struttura principale mediante adeguate zanche annegate nel muro o viti di fissaggio. Vetro: 66.2 COOL-LITE 70-33#2 / 14mm (aria-argon 90%) / 27 CF60-3. Comprese lamiere di raccordo, memebrane e isolanti. | D16: 1200 | F16: 3000 | G16: =(D16*F16)/1000000 -> 3.6 | H16: 3 | I16: =G16*H16 -> 10.8 | K16: =J16*$K$5 -> 0 | L16: =K16*$L$5 -> 0 | M16: =L16*$M$5 -> 0 | N16: =M16 -> 0 | O16: =N16*H16 -> 0 | P16: 0 | Q16: =P16*$Q$5 -> 0 | R16: 0 | S16: =R16*H16 -> 0 | U16: =T16*$U$5 -> 0 | V16: =U16 -> 0 | W16: =V16*H16 -> 0 | X16: =($X$5*2*(D16+F16))/1000 -> 184.8 | Y16: =X16*$Y$5 -> 184.8 | Z16: =Y16*$Z$5 -> 184.8 | AA16: =Z16*$AA$5 -> 184.8 | AB16: =AA16 -> 184.8 | AC16: =AB16*H16 -> 554.4 | AD16: =$AD$6*G16 -> 100.8 | AE16: =AD16*H16 -> 302.4 | AF16: 1650 | AG16: =AF16*H16 -> 4950 | AI16: =AH16*H16 -> 0 | AJ16: 0 | AK16: =AJ16*H16 -> 0 | AL16: 0 | AM16: =AL16*H16 -> 0 | AN16: =$AN$8*G16 -> 2142 | AO16: =AN16*H16 -> 6426 | AP16: 0 | AQ16: =AP16*H16 -> 0 | AR16: =($AR$6*2*(D16+F16))/1000 -> 378 | AS16: =AR16*H16 -> 1134 | AT16: 735 | AU16: =AT16*H16 -> 2205 | AV16: =AV8 -> 1286 | AW16: =AV16*H16 -> 3858 | AX16: 0 | AY16: =AX16*H16 -> 0 | AZ16: =$AZ$8*G16 -> 0 | BA16: =AZ16*H16 -> 0 | BB16: =N16+R16+V16+AB16+AD16+AF16+AH16+AJ16+AL16+AN16+AP16+AR16+AT16+AV16+AX16+AZ16 -> 6476.6 | BC16: =O16+S16+W16+AC16+AE16+AG16+AI16+AK16+AM16+AO16+AQ16+AS16+AU16+AW16+AY16+BA16 -> 19429.8 | BD16: =BC16/I16 -> 1799.0556 | BE16: =BB16*$BE$5 -> 77.7192 | BF16: =BC16*$BE$5 -> 233.1576 | BG16: =BB16*$BG$5 -> 97.149 | BH16: =BC16*$BG$5 -> 291.447 | BI16: =BB16*$BI$5 -> 32.383 | BJ16: =BC16*$BI$5 -> 97.149 | BK16: =BB16*$BK$5 -> 64.766 | BL16: =BC16*$BK$5 -> 194.298 | BM16: =$BM$5 -> 0 | BN16: =BB16*BM16 -> 0 | BO16: =BC16*BM$12 -> 0 | BP16: =$BP$5 -> 0.32 | BQ16: =BB16*$BP16 -> 2072.512 | BR16: =BC16*BP16 -> 6217.536 | BS16: =BB16+BE16+BG16+BI16+BK16+BN16+BQ16 -> 8821.1292 | BT16: =BC16+BF16+BH16+BJ16+BL16+BO16+BR16 -> 26463.388 | BU16: =BT16/I16 -> 2450.3137
B17: F3a | C17: Porta a doppio battente apertura interno dell’edificio con pushbar esterno e chiudiporta, presenza di sopraluce fisso è presente un ulteriore sopraluce curvo con presenza di lamelle di areazione. Il serramento presente una prestazione EI60 escluso la parte lamellata. SOSTITUITO CON ALLUMINIO Reynaers ConceptSystem 77-FP EI 60 (CS 77-FPEI60) Compreso controtelaio costituito da profili in legno sagomato a L, adeguatamente trattato per evitare formazione di muffe o deformazioni geometriche, ancorato alla struttura principale mediante adeguate zanche annegate nel muro o viti di fissaggio. Vetro: 66.2 COOL-LITE 70-33#2 / 14mm (aria-argon 90%) / 27 CF60-3. Comprese lamiere di raccordo, memebrane e isolanti. | D17: 1200 | F17: 3000 | G17: =(D17*F17)/1000000 -> 3.6 | H17: 1 | I17: =G17*H17 -> 3.6 | K17: =J17*$K$5 -> 0 | L17: =K17*$L$5 -> 0 | M17: =L17*$M$5 -> 0 | N17: =M17 -> 0 | O17: =N17*H17 -> 0 | P17: 0 | Q17: =P17*$Q$5 -> 0 | R17: 0 | S17: =R17*H17 -> 0 | T17: =$T$5 -> 650 | U17: =T17*$U$5 -> 650 | V17: =U17 -> 650 | W17: =V17*H17 -> 650 | X17: =($X$5*2*(D17+F17))/1000 -> 184.8 | Y17: =X17*$Y$5 -> 184.8 | Z17: =Y17*$Z$5 -> 184.8 | AA17: =Z17*$AA$5 -> 184.8 | AB17: =AA17 -> 184.8 | AC17: =AB17*H17 -> 184.8 | AD17: =$AD$5*G17 -> 54 | AE17: =AD17*H17 -> 54 | AF17: 938 | AG17: =AF17*H17 -> 938 | AI17: =AH17*H17 -> 0 | AJ17: 0 | AK17: =AJ17*H17 -> 0 | AL17: =$AL$5 -> 60 | AM17: =AL17*H17 -> 60 | AN17: =$AN$7*G17 -> 972 | AO17: =AN17*H17 -> 972 | AP17: 0 | AQ17: =AP17*H17 -> 0 | AR17: =($AR$5*2*(D17+F17))/1000 -> 294 | AS17: =AR17*H17 -> 294 | AT17: 935 | AU17: =AT17*H17 -> 935 | AV17: =$AV$5*G17 -> 477 | AW17: =AV17*H17 -> 477 | AX17: 0 | AY17: =AX17*H17 -> 0 | AZ17: =$AZ$8*G17 -> 0 | BA17: =AZ17*H17 -> 0 | BB17: =N17+R17+V17+AB17+AD17+AF17+AH17+AJ17+AL17+AN17+AP17+AR17+AT17+AV17+AX17+AZ17 -> 4564.8 | BC17: =O17+S17+W17+AC17+AE17+AG17+AI17+AK17+AM17+AO17+AQ17+AS17+AU17+AW17+AY17+BA17 -> 4564.8 | BD17: =BC17/I17 -> 1268 | BE17: =BB17*$BE$5 -> 54.7776 | BF17: =BC17*$BE$5 -> 54.7776 | BG17: =BB17*$BG$5 -> 68.472 | BH17: =BC17*$BG$5 -> 68.472 | BI17: =BB17*$BI$5 -> 22.824 | BJ17: =BC17*$BI$5 -> 22.824 | BK17: =BB17*$BK$5 -> 45.648 | BL17: =BC17*$BK$5 -> 45.648 | BM17: =$BM$5 -> 0 | BN17: =BB17*BM17 -> 0 | BO17: =BC17*BM$12 -> 0 | BP17: =$BP$5 -> 0.32 | BQ17: =BB17*$BP17 -> 1460.736 | BR17: =BC17*BP17 -> 1460.736 | BS17: =BB17+BE17+BG17+BI17+BK17+BN17+BQ17 -> 6217.2576 | BT17: =BC17+BF17+BH17+BJ17+BL17+BO17+BR17 -> 6217.2576 | BU17: =BT17/I17 -> 1727.016
B18: F3b | C18: Serramento con specchiature vision fisse è presente un ulteriore sopraluce curvo con presenza di lamelle di areazione. Il serramento presenta una prestazione EI60 escluso la parte lamellata.SOSTITUITO CON ALLUMINIO Reynaers ConceptSystem 77-FP EI 60 (CS 77-FPEI60) Compreso controtelaio costituito da profili in legno sagomato a L, adeguatamente trattato per evitare formazione di muffe o deformazioni geometriche, ancorato alla struttura principale mediante adeguate zanche annegate nel muro o viti di fissaggio. Vetro: 66.2 COOL-LITE 70-33#2 / 14mm (aria-argon 90%) / 27 CF60-3. Comprese lamiere di raccordo, memebrane e isolanti. | D18: 1200 | F18: 3000 | G18: =(D18*F18)/1000000 -> 3.6 | H18: 2 | I18: =G18*H18 -> 7.2 | K18: =J18*$K$5 -> 0 | L18: =K18*$L$5 -> 0 | M18: =L18*$M$5 -> 0 | N18: =M18 -> 0 | O18: =N18*H18 -> 0 | P18: 0 | Q18: =P18*$Q$5 -> 0 | R18: 0 | S18: =R18*H18 -> 0 | T18: =$T$5 -> 650 | U18: =T18*$U$5 -> 650 | V18: =U18 -> 650 | W18: =V18*H18 -> 1300 | X18: =($X$5*2*(D18+F18))/1000 -> 184.8 | Y18: =X18*$Y$5 -> 184.8 | Z18: =Y18*$Z$5 -> 184.8 | AA18: =Z18*$AA$5 -> 184.8 | AB18: =AA18 -> 184.8 | AC18: =AB18*H18 -> 369.6 | AD18: =$AD$5*G18 -> 54 | AE18: =AD18*H18 -> 108 | AF18: 938 | AG18: =AF18*H18 -> 1876 | AI18: =AH18*H18 -> 0 | AJ18: 0 | AK18: =AJ18*H18 -> 0 | AL18: =$AL$5 -> 60 | AM18: =AL18*H18 -> 120 | AN18: =$AN$7*G18 -> 972 | AO18: =AN18*H18 -> 1944 | AP18: 0 | AQ18: =AP18*H18 -> 0 | AR18: =($AR$5*2*(D18+F18))/1000 -> 294 | AS18: =AR18*H18 -> 588 | AT18: =1870/2 -> 935 | AU18: =AT18*H18 -> 1870 | AV18: =$AV$5*G18 -> 477 | AW18: =AV18*H18 -> 954 | AX18: 0 | AY18: =AX18*H18 -> 0 | AZ18: =$AZ$8*G18 -> 0 | BA18: =AZ18*H18 -> 0 | BB18: =N18+R18+V18+AB18+AD18+AF18+AH18+AJ18+AL18+AN18+AP18+AR18+AT18+AV18+AX18+AZ18 -> 4564.8 | BC18: =O18+S18+W18+AC18+AE18+AG18+AI18+AK18+AM18+AO18+AQ18+AS18+AU18+AW18+AY18+BA18 -> 9129.6 | BD18: =BC18/I18 -> 1268 | BE18: =BB18*$BE$5 -> 54.7776 | BF18: =BC18*$BE$5 -> 109.5552 | BG18: =BB18*$BG$5 -> 68.472 | BH18: =BC18*$BG$5 -> 136.944 | BI18: =BB18*$BI$5 -> 22.824 | BJ18: =BC18*$BI$5 -> 45.648 | BK18: =BB18*$BK$5 -> 45.648 | BL18: =BC18*$BK$5 -> 91.296 | BM18: =$BM$5 -> 0 | BN18: =BB18*BM18 -> 0 | BO18: =BC18*BM$12 -> 0 | BP18: =$BP$5 -> 0.32 | BQ18: =BB18*$BP18 -> 1460.736 | BR18: =BC18*BP18 -> 2921.472 | BS18: =BB18+BE18+BG18+BI18+BK18+BN18+BQ18 -> 6217.2576 | BT18: =BC18+BF18+BH18+BJ18+BL18+BO18+BR18 -> 12434.515 | BU18: =BT18/I18 -> 1727.016
B19: F4a | C19: Serramento in acciaio con volta circolare apribile a vasistas meccanizzato e automatico specchiatura inferiore con porta a doppio battente apertura esterna, sopraluce rettangolare fisso. SOSTITUITO CON ALLUMINIO Reynaers ConceptSystem 77-FP EI 60 (CS 77-FPEI60) Controtelaio composto da tubi rettangolari ancorato alla struttura principale mediante adeguate zanche annegate nel muro o viti di fissaggio, il telaio deve essere correttamente isolato e zincato per proteggerlo dalla corrosione. Vetro: 66.2 COOL-LITE 70-33#2 / 14mm (aria-argon 90%) / 27 CF60-3. Comprese lamiere di raccordo, memebrane e isolanti. | D19: 1300 | F19: 3000 | G19: =(D19*F19)/1000000 -> 3.9 | H19: 1 | I19: =G19*H19 -> 3.9 | K19: =J19*$K$5 -> 0 | L19: =K19*$L$5 -> 0 | M19: =L19*$M$5 -> 0 | N19: =M19 -> 0 | O19: =N19*H19 -> 0 | P19: 0 | Q19: =P19*$Q$5 -> 0 | R19: 0 | S19: =R19*H19 -> 0 | T19: =$T$5 -> 650 | U19: =T19*$U$5 -> 650 | V19: =U19 -> 650 | W19: =V19*H19 -> 650 | X19: =($X$5*2*(D19+F19))/1000 -> 189.2 | Y19: =X19*$Y$5 -> 189.2 | Z19: =Y19*$Z$5 -> 189.2 | AA19: =Z19*$AA$5 -> 189.2 | AB19: =AA19 -> 189.2 | AC19: =AB19*H19 -> 189.2 | AD19: =$AD$5*G19 -> 58.5 | AE19: =AD19*H19 -> 58.5 | AF19: 1450 | AG19: =AF19*H19 -> 1450 | AI19: =AH19*H19 -> 0 | AJ19: 0 | AK19: =AJ19*H19 -> 0 | AL19: =$AL$5 -> 60 | AM19: =AL19*H19 -> 60 | AN19: =$AN$7*G19 -> 1053 | AO19: =AN19*H19 -> 1053 | AP19: 0 | AQ19: =AP19*H19 -> 0 | AR19: =($AR$5*2*(D19+F19))/1000 -> 301 | AS19: =AR19*H19 -> 301 | AT19: 0 | AU19: =AT19*H19 -> 0 | AV19: =$AV$5*G19 -> 516.75 | AW19: =AV19*H19 -> 516.75 | AX19: 0 | AY19: =AX19*H19 -> 0 | AZ19: =$AZ$8*G19 -> 0 | BA19: =AZ19*H19 -> 0 | BB19: =N19+R19+V19+AB19+AD19+AF19+AH19+AJ19+AL19+AN19+AP19+AR19+AT19+AV19+AX19+AZ19 -> 4278.45 | BC19: =O19+S19+W19+AC19+AE19+AG19+AI19+AK19+AM19+AO19+AQ19+AS19+AU19+AW19+AY19+BA19 -> 4278.45 | BD19: =BC19/I19 -> 1097.0385 | BE19: =BB19*$BE$5 -> 51.3414 | BF19: =BC19*$BE$5 -> 51.3414 | BG19: =BB19*$BG$5 -> 64.17675 | BH19: =BC19*$BG$5 -> 64.17675 | BI19: =BB19*$BI$5 -> 21.39225 | BJ19: =BC19*$BI$5 -> 21.39225 | BK19: =BB19*$BK$5 -> 42.7845 | BL19: =BC19*$BK$5 -> 42.7845 | BM19: =$BM$5 -> 0 | BN19: =BB19*BM19 -> 0 | BO19: =BC19*BM$12 -> 0 | BP19: =$BP$5 -> 0.32 | BQ19: =BB19*$BP19 -> 1369.104 | BR19: =BC19*BP19 -> 1369.104 | BS19: =BB19+BE19+BG19+BI19+BK19+BN19+BQ19 -> 5827.2489 | BT19: =BC19+BF19+BH19+BJ19+BL19+BO19+BR19 -> 5827.2489 | BU19: =BT19/I19 -> 1494.1664
B20: F4b | C20: Porta a doppio battente vetrata, apertura doppia anta verso l’esterno, sopraluce fisso. Compreso controtelaio costituito da profili in legno sagomato a L, adeguatamente trattato per evitare formazione di muffe o deformazioni geometriche, ancorato alla struttura principale mediante adeguate zanche annegate nel muro o viti di fissaggio. Vetro: 66.2 COOL-LITE 70-33#2 INDURITI / 20mm (aria-argon 90%) / 55.2 int. RICOTTI Comprese lamiere di raccordo, memebrane e isolanti. | D20: 1300 | F20: 3000 | G20: =(D20*F20)/1000000 -> 3.9 | H20: 1 | I20: =G20*H20 -> 3.9 | K20: =J20*$K$5 -> 0 | L20: =K20*$L$5 -> 0 | M20: =L20*$M$5 -> 0 | N20: =M20 -> 0 | O20: =N20*H20 -> 0 | P20: 0 | Q20: =P20*$Q$5 -> 0 | R20: 0 | S20: =R20*H20 -> 0 | T20: =$T$5 -> 650 | U20: =T20*$U$5 -> 650 | V20: =U20 -> 650 | W20: =V20*H20 -> 650 | X20: =($X$5*2*(D20+F20))/1000 -> 189.2 | Y20: =X20*$Y$5 -> 189.2 | Z20: =Y20*$Z$5 -> 189.2 | AA20: =Z20*$AA$5 -> 189.2 | AB20: =AA20 -> 189.2 | AC20: =AB20*H20 -> 189.2 | AD20: =$AD$5*G20 -> 58.5 | AE20: =AD20*H20 -> 58.5 | AF20: 1420 | AG20: =AF20*H20 -> 1420 | AI20: =AH20*H20 -> 0 | AJ20: 0 | AK20: =AJ20*H20 -> 0 | AL20: =$AL$5 -> 60 | AM20: =AL20*H20 -> 60 | AN20: =$AN$7*G20 -> 1053 | AO20: =AN20*H20 -> 1053 | AP20: 0 | AQ20: =AP20*H20 -> 0 | AR20: =($AR$5*2*(D20+F20))/1000 -> 301 | AS20: =AR20*H20 -> 301 | AT20: 1650 | AU20: =AT20*H20 -> 1650 | AV20: =$AV$5*G20 -> 516.75 | AW20: =AV20*H20 -> 516.75 | AX20: 0 | AY20: =AX20*H20 -> 0 | AZ20: =$AZ$8*G20 -> 0 | BA20: =AZ20*H20 -> 0 | BB20: =N20+R20+V20+AB20+AD20+AF20+AH20+AJ20+AL20+AN20+AP20+AR20+AT20+AV20+AX20+AZ20 -> 5898.45 | BC20: =O20+S20+W20+AC20+AE20+AG20+AI20+AK20+AM20+AO20+AQ20+AS20+AU20+AW20+AY20+BA20 -> 5898.45 | BD20: =BC20/I20 -> 1512.4231 | BE20: =BB20*$BE$5 -> 70.7814 | BF20: =BC20*$BE$5 -> 70.7814 | BG20: =BB20*$BG$5 -> 88.47675 | BH20: =BC20*$BG$5 -> 88.47675 | BI20: =BB20*$BI$5 -> 29.49225 | BJ20: =BC20*$BI$5 -> 29.49225 | BK20: =BB20*$BK$5 -> 58.9845 | BL20: =BC20*$BK$5 -> 58.9845 | BM20: =$BM$5 -> 0 | BN20: =BB20*BM20 -> 0 | BO20: =BC20*BM$12 -> 0 | BP20: =$BP$5 -> 0.32 | BQ20: =BB20*$BP20 -> 1887.504 | BR20: =BC20*BP20 -> 1887.504 | BS20: =BB20+BE20+BG20+BI20+BK20+BN20+BQ20 -> 8033.6889 | BT20: =BC20+BF20+BH20+BJ20+BL20+BO20+BR20 -> 8033.6889 | BU20: =BT20/I20 -> 2059.9202
A21: EI | B21: F5a - EI60 Serramento in acciaio EI60 tipo Secco EBE85 | C21: Porta a doppio battente apertura interno dell’edificio con pushbar esterno e chiudiporta, presenza di sopraluce fisso è presente un ulteriore sopraluce curvo con presenza di lamelle di areazione. Il serramento presente una prestazione EI60 escluso la parte lamellata. SOSTITUITO CON ALLUMINIO Reynaers ConceptSystem 77-FP EI 60 (CS 77-FPEI60) Compreso controtelaio costituito da profili in legno sagomato a L, adeguatamente trattato per evitare formazione di muffe o deformazioni geometriche, ancorato alla struttura principale mediante adeguate zanche annegate nel muro o viti di fissaggio. Vetro: 66.2 COOL-LITE 70-33#2 / 14mm (aria-argon 90%) / 27 CF60-3. Comprese lamiere di raccordo, memebrane e isolanti. | D21: 1600 | F21: 3530 | G21: =(D21*F21)/1000000 -> 5.648 | H21: 1 | I21: =G21*H21 -> 5.648 | K21: =J21*$K$5 -> 0 | L21: =K21*$L$5 -> 0 | M21: =L21*$M$5 -> 0 | N21: =M21 -> 0 | O21: =N21*H21 -> 0 | P21: 0 | Q21: =P21*$Q$5 -> 0 | R21: 0 | S21: =R21*H21 -> 0 | T21: =$T$6 -> 1930 | U21: =T21*$U$5 -> 1930 | V21: =U21 -> 1930 | W21: =V21*H21 -> 1930 | X21: =($X$5*2*(D21+F21))/1000 -> 225.72 | Y21: =X21*$Y$5 -> 225.72 | Z21: =Y21*$Z$5 -> 225.72 | AA21: =Z21*$AA$5 -> 225.72 | AB21: =AA21 -> 225.72 | AC21: =AB21*H21 -> 225.72 | AD21: =$AD$6*G21 -> 158.144 | AE21: =AD21*H21 -> 158.144 | AF21: =3438+748 -> 4186 | AG21: =AF21*H21 -> 4186 | AI21: =AH21*H21 -> 0 | AJ21: 0 | AK21: =AJ21*H21 -> 0 | AL21: =$AL$5 -> 60 | AM21: =AL21*H21 -> 60 | AN21: =$AN$8*G21 -> 3360.56 | AO21: =AN21*H21 -> 3360.56 | AP21: 0 | AQ21: =AP21*H21 -> 0 | AR21: =($AR$6*2*(D21+F21))/1000 -> 461.7 | AS21: =AR21*H21 -> 461.7 | AT21: 3025 | AU21: =AT21*H21 -> 3025 | AV21: =$AV$8 -> 1286 | AW21: =AV21*H21 -> 1286 | AX21: 0 | AY21: =AX21*H21 -> 0 | AZ21: =$AZ$8*G21 -> 0 | BA21: =AZ21*H21 -> 0 | BB21: =N21+R21+V21+AB21+AD21+AF21+AH21+AJ21+AL21+AN21+AP21+AR21+AT21+AV21+AX21+AZ21 -> 14693.124 | BC21: =O21+S21+W21+AC21+AE21+AG21+AI21+AK21+AM21+AO21+AQ21+AS21+AU21+AW21+AY21+BA21 -> 14693.124 | BD21: =BC21/I21 -> 2601.4738 | BE21: =BB21*$BE$5 -> 176.31749 | BF21: =BC21*$BE$5 -> 176.31749 | BG21: =BB21*$BG$5 -> 220.39686 | BH21: =BC21*$BG$5 -> 220.39686 | BI21: =BB21*$BI$5 -> 73.46562 | BJ21: =BC21*$BI$5 -> 73.46562 | BK21: =BB21*$BK$5 -> 146.93124 | BL21: =BC21*$BK$5 -> 146.93124 | BM21: =$BM$5 -> 0 | BN21: =BB21*BM21 -> 0 | BO21: =BC21*BM$12 -> 0 | BP21: =$BP$5 -> 0.32 | BQ21: =BB21*$BP21 -> 4701.7997 | BR21: =BC21*BP21 -> 4701.7997 | BS21: =BB21+BE21+BG21+BI21+BK21+BN21+BQ21 -> 20012.035 | BT21: =BC21+BF21+BH21+BJ21+BL21+BO21+BR21 -> 20012.035 | BU21: =BT21/I21 -> 3543.2073
A22: EI | B22: F5b - EI60 Serramento in acciaio EI60 tipo Secco EBE85 | C22: Serramento con specchiature vision fisse è presente un ulteriore sopraluce curvo con presenza di lamelle di areazione. Il serramento presenta una prestazione EI60 escluso la parte lamellata.SOSTITUITO CON ALLUMINIO Reynaers ConceptSystem 77-FP EI 60 (CS 77-FPEI60) Compreso controtelaio costituito da profili in legno sagomato a L, adeguatamente trattato per evitare formazione di muffe o deformazioni geometriche, ancorato alla struttura principale mediante adeguate zanche annegate nel muro o viti di fissaggio. Vetro: 66.2 COOL-LITE 70-33#2 / 14mm (aria-argon 90%) / 27 CF60-3. Comprese lamiere di raccordo, memebrane e isolanti. | D22: 1600 | F22: 3530 | G22: =(D22*F22)/1000000 -> 5.648 | H22: 1 | I22: =G22*H22 -> 5.648 | K22: =J22*$K$5 -> 0 | L22: =K22*$L$5 -> 0 | M22: =L22*$M$5 -> 0 | N22: =M22 -> 0 | O22: =N22*H22 -> 0 | P22: 0 | Q22: =P22*$Q$5 -> 0 | R22: 0 | S22: =R22*H22 -> 0 | T22: 0 | U22: =T22*$U$5 -> 0 | V22: =U22 -> 0 | W22: =V22*H22 -> 0 | X22: =($X$5*2*(D22+F22))/1000 -> 225.72 | Y22: =X22*$Y$5 -> 225.72 | Z22: =Y22*$Z$5 -> 225.72 | AA22: =Z22*$AA$5 -> 225.72 | AB22: =AA22 -> 225.72 | AC22: =AB22*H22 -> 225.72 | AD22: =$AD$6*G22 -> 158.144 | AE22: =AD22*H22 -> 158.144 | AF22: =1671+1520+818 -> 4009 | AG22: =AF22*H22 -> 4009 | AI22: =AH22*H22 -> 0 | AJ22: 0 | AK22: =AJ22*H22 -> 0 | AL22: =$AL$5 -> 60 | AM22: =AL22*H22 -> 60 | AN22: =$AN$8*G22 -> 3360.56 | AO22: =AN22*H22 -> 3360.56 | AP22: 0 | AQ22: =AP22*H22 -> 0 | AR22: =($AR$6*2*(D22+F22))/1000 -> 461.7 | AS22: =AR22*H22 -> 461.7 | AT22: 2035 | AU22: =AT22*H22 -> 2035 | AV22: =$AV$8 -> 1286 | AW22: =AV22*H22 -> 1286 | AX22: 0 | AY22: =AX22*H22 -> 0 | AZ22: =$AZ$8*G22 -> 0 | BA22: =AZ22*H22 -> 0 | BB22: =N22+R22+V22+AB22+AD22+AF22+AH22+AJ22+AL22+AN22+AP22+AR22+AT22+AV22+AX22+AZ22 -> 11596.124 | BC22: =O22+S22+W22+AC22+AE22+AG22+AI22+AK22+AM22+AO22+AQ22+AS22+AU22+AW22+AY22+BA22 -> 11596.124 | BD22: =BC22/I22 -> 2053.1381 | BE22: =BB22*$BE$5 -> 139.15349 | BF22: =BC22*$BE$5 -> 139.15349 | BG22: =BB22*$BG$5 -> 173.94186 | BH22: =BC22*$BG$5 -> 173.94186 | BI22: =BB22*$BI$5 -> 57.98062 | BJ22: =BC22*$BI$5 -> 57.98062 | BK22: =BB22*$BK$5 -> 115.96124 | BL22: =BC22*$BK$5 -> 115.96124 | BM22: =$BM$5 -> 0 | BN22: =BB22*BM22 -> 0 | BO22: =BC22*BM$12 -> 0 | BP22: =$BP$5 -> 0.32 | BQ22: =BB22*$BP22 -> 3710.7597 | BR22: =BC22*BP22 -> 3710.7597 | BS22: =BB22+BE22+BG22+BI22+BK22+BN22+BQ22 -> 15793.921 | BT22: =BC22+BF22+BH22+BJ22+BL22+BO22+BR22 -> 15793.921 | BU22: =BT22/I22 -> 2796.3741
B23: F6 | C23: Serramento portafinestra in legno doppia anta battente apertura interna fissato solidamente ad un controtelaio in profili di legno adeguatamente trattato e isolato. Compreso controtelaio costituito da profili in legno sagomato a L, adeguatamente trattato per evitare formazione di muffe o deformazioni geometriche, ancorato alla struttura principale mediante adeguate zanche annegate nel muro o viti di fissaggio. Vetro: 66.2 COOL-LITE 70-33#2 INDURITI / 20mm (aria-argon 90%) / 55.2 int. RICOTTI Comprese lamiere di raccordo, memebrane e isolanti. | D23: 1300 | F23: 2950 | G23: =(D23*F23)/1000000 -> 3.835 | H23: 11 | I23: =G23*H23 -> 42.185 | K23: =J23*$K$5 -> 0 | L23: =K23*$L$5 -> 0 | M23: =L23*$M$5 -> 0 | N23: =M23 -> 0 | O23: =N23*H23 -> 0 | P23: 0 | Q23: =P23*$Q$5 -> 0 | R23: 0 | S23: =R23*H23 -> 0 | T23: =$T$5 -> 650 | U23: =T23*$U$5 -> 650 | V23: =U23 -> 650 | W23: =V23*H23 -> 7150 | X23: =($X$5*2*(D23+F23))/1000 -> 187 | Y23: =X23*$Y$5 -> 187 | Z23: =Y23*$Z$5 -> 187 | AA23: =Z23*$AA$5 -> 187 | AB23: =AA23 -> 187 | AC23: =AB23*H23 -> 2057 | AD23: =$AD$5*G23 -> 57.525 | AE23: =AD23*H23 -> 632.775 | AF23: 934 | AG23: =AF23*H23 -> 10274 | AI23: =AH23*H23 -> 0 | AJ23: 0 | AK23: =AJ23*H23 -> 0 | AL23: =$AL$5 -> 60 | AM23: =AL23*H23 -> 660 | AN23: =$AN$7*G23 -> 1035.45 | AO23: =AN23*H23 -> 11389.95 | AP23: 0 | AQ23: =AP23*H23 -> 0 | AR23: =($AR$5*2*(D23+F23))/1000 -> 297.5 | AS23: =AR23*H23 -> 3272.5 | AT23: =10285/10 -> 1028.5 | AU23: =AT23*H23 -> 11313.5 | AV23: =$AV$5*G23 -> 508.1375 | AW23: =AV23*H23 -> 5589.5125 | AX23: 0 | AY23: =AX23*H23 -> 0 | AZ23: =$AZ$8*G23 -> 0 | BA23: =AZ23*H23 -> 0 | BB23: =N23+R23+V23+AB23+AD23+AF23+AH23+AJ23+AL23+AN23+AP23+AR23+AT23+AV23+AX23+AZ23 -> 4758.1125 | BC23: =O23+S23+W23+AC23+AE23+AG23+AI23+AK23+AM23+AO23+AQ23+AS23+AU23+AW23+AY23+BA23 -> 52339.238 | BD23: =BC23/I23 -> 1240.7073 | BE23: =BB23*$BE$5 -> 57.09735 | BF23: =BC23*$BE$5 -> 628.07085 | BG23: =BB23*$BG$5 -> 71.371687 | BH23: =BC23*$BG$5 -> 785.08856 | BI23: =BB23*$BI$5 -> 23.790563 | BJ23: =BC23*$BI$5 -> 261.69619 | BK23: =BB23*$BK$5 -> 47.581125 | BL23: =BC23*$BK$5 -> 523.39238 | BM23: =$BM$5 -> 0 | BN23: =BB23*BM23 -> 0 | BO23: =BC23*BM$12 -> 0 | BP23: =$BP$5 -> 0.32 | BQ23: =BB23*$BP23 -> 1522.596 | BR23: =BC23*BP23 -> 16748.556 | BS23: =BB23+BE23+BG23+BI23+BK23+BN23+BQ23 -> 6480.5492 | BT23: =BC23+BF23+BH23+BJ23+BL23+BO23+BR23 -> 71286.041 | BU23: =BT23/I23 -> 1689.8433
B24: F6a | C24: Serramento portafinestra in legno doppia anta battente apertura interna fissato solidamente ad un controtelaio in profili di legno adeguatamente trattato e isolato. SERRAMENTO A TENUTA FUMI. Compreso controtelaio costituito da profili in legno sagomato a L, adeguatamente trattato per evitare formazione di muffe o deformazioni geometriche, ancorato alla struttura principale mediante adeguate zanche annegate nel muro o viti di fissaggio. Vetro: 66.2 COOL-LITE 70-33#2 INDURITI / 20mm (aria-argon 90%) / 55.2 int. RICOTTI Comprese lamiere di raccordo, memebrane e isolanti. | D24: 1300 | F24: 2950 | G24: =(D24*F24)/1000000 -> 3.835 | H24: 3 | I24: =G24*H24 -> 11.505 | K24: =J24*$K$5 -> 0 | L24: =K24*$L$5 -> 0 | M24: =L24*$M$5 -> 0 | N24: =M24 -> 0 | O24: =N24*H24 -> 0 | P24: 0 | Q24: =P24*$Q$5 -> 0 | R24: 0 | S24: =R24*H24 -> 0 | T24: =$T$5 -> 650 | U24: =T24*$U$5 -> 650 | V24: =U24 -> 650 | W24: =V24*H24 -> 1950 | X24: =($X$5*2*(D24+F24))/1000 -> 187 | Y24: =X24*$Y$5 -> 187 | Z24: =Y24*$Z$5 -> 187 | AA24: =Z24*$AA$5 -> 187 | AB24: =AA24 -> 187 | AC24: =AB24*H24 -> 561 | AD24: =$AD$5*G24 -> 57.525 | AE24: =AD24*H24 -> 172.575 | AF24: 934 | AG24: =AF24*H24 -> 2802 | AI24: =AH24*H24 -> 0 | AJ24: 0 | AK24: =AJ24*H24 -> 0 | AL24: =$AL$5 -> 60 | AM24: =AL24*H24 -> 180 | AN24: =$AN$7*G24 -> 1035.45 | AO24: =AN24*H24 -> 3106.35 | AP24: 0 | AQ24: =AP24*H24 -> 0 | AR24: =($AR$5*2*(D24+F24))/1000 -> 297.5 | AS24: =AR24*H24 -> 892.5 | AT24: =2805/3 -> 935 | AU24: =AT24*H24 -> 2805 | AV24: =$AV$5*G24 -> 508.1375 | AW24: =AV24*H24 -> 1524.4125 | AX24: 0 | AY24: =AX24*H24 -> 0 | AZ24: =$AZ$8*G24 -> 0 | BA24: =AZ24*H24 -> 0 | BB24: =N24+R24+V24+AB24+AD24+AF24+AH24+AJ24+AL24+AN24+AP24+AR24+AT24+AV24+AX24+AZ24 -> 4664.6125 | BC24: =O24+S24+W24+AC24+AE24+AG24+AI24+AK24+AM24+AO24+AQ24+AS24+AU24+AW24+AY24+BA24 -> 13993.837 | BD24: =BC24/I24 -> 1216.3266 | BE24: =BB24*$BE$5 -> 55.97535 | BF24: =BC24*$BE$5 -> 167.92605 | BG24: =BB24*$BG$5 -> 69.969188 | BH24: =BC24*$BG$5 -> 209.90756 | BI24: =BB24*$BI$5 -> 23.323063 | BJ24: =BC24*$BI$5 -> 69.969188 | BK24: =BB24*$BK$5 -> 46.646125 | BL24: =BC24*$BK$5 -> 139.93838 | BM24: =$BM$5 -> 0 | BN24: =BB24*BM24 -> 0 | BO24: =BC24*BM$12 -> 0 | BP24: =$BP$5 -> 0.32 | BQ24: =BB24*$BP24 -> 1492.676 | BR24: =BC24*BP24 -> 4478.028 | BS24: =BB24+BE24+BG24+BI24+BK24+BN24+BQ24 -> 6353.2022 | BT24: =BC24+BF24+BH24+BJ24+BL24+BO24+BR24 -> 19059.607 | BU24: =BT24/I24 -> 1656.6368
B25: F6b | C25: Serramento portafinestra in legno doppia anta battente apertura esterna fissato solidamente ad un controtelaio in profili di legno adeguatamente trattato e isolato. SERRAMENTO A TENUTA FUMI. Compreso controtelaio costituito da profili in legno sagomato a L, adeguatamente trattato per evitare formazione di muffe o deformazioni geometriche, ancorato alla struttura principale mediante adeguate zanche annegate nel muro o viti di fissaggio. Vetro: 66.2 COOL-LITE 70-33#2 INDURITI / 20mm (aria-argon 90%) / 55.2 int. RICOTTI Comprese lamiere di raccordo, memebrane e isolanti. | D25: 1300 | F25: 2950 | G25: =(D25*F25)/1000000 -> 3.835 | H25: 1 | I25: =G25*H25 -> 3.835 | K25: =J25*$K$5 -> 0 | L25: =K25*$L$5 -> 0 | M25: =L25*$M$5 -> 0 | N25: =M25 -> 0 | O25: =N25*H25 -> 0 | P25: 0 | Q25: =P25*$Q$5 -> 0 | R25: 0 | S25: =R25*H25 -> 0 | T25: =$T$5 -> 650 | U25: =T25*$U$5 -> 650 | V25: =U25 -> 650 | W25: =V25*H25 -> 650 | X25: =($X$5*2*(D25+F25))/1000 -> 187 | Y25: =X25*$Y$5 -> 187 | Z25: =Y25*$Z$5 -> 187 | AA25: =Z25*$AA$5 -> 187 | AB25: =AA25 -> 187 | AC25: =AB25*H25 -> 187 | AD25: =$AD$5*G25 -> 57.525 | AE25: =AD25*H25 -> 57.525 | AF25: 934 | AG25: =AF25*H25 -> 934 | AI25: =AH25*H25 -> 0 | AJ25: 0 | AK25: =AJ25*H25 -> 0 | AL25: =$AL$5 -> 60 | AM25: =AL25*H25 -> 60 | AN25: =$AN$7*G25 -> 1035.45 | AO25: =AN25*H25 -> 1035.45 | AP25: 0 | AQ25: =AP25*H25 -> 0 | AR25: =($AR$5*2*(D25+F25))/1000 -> 297.5 | AS25: =AR25*H25 -> 297.5 | AT25: 935 | AU25: =AT25*H25 -> 935 | AV25: =$AV$5*G25 -> 508.1375 | AW25: =AV25*H25 -> 508.1375 | AX25: 0 | AY25: =AX25*H25 -> 0 | AZ25: =$AZ$8*G25 -> 0 | BA25: =AZ25*H25 -> 0 | BB25: =N25+R25+V25+AB25+AD25+AF25+AH25+AJ25+AL25+AN25+AP25+AR25+AT25+AV25+AX25+AZ25 -> 4664.6125 | BC25: =O25+S25+W25+AC25+AE25+AG25+AI25+AK25+AM25+AO25+AQ25+AS25+AU25+AW25+AY25+BA25 -> 4664.6125 | BD25: =BC25/I25 -> 1216.3266 | BE25: =BB25*$BE$5 -> 55.97535 | BF25: =BC25*$BE$5 -> 55.97535 | BG25: =BB25*$BG$5 -> 69.969188 | BH25: =BC25*$BG$5 -> 69.969188 | BI25: =BB25*$BI$5 -> 23.323063 | BJ25: =BC25*$BI$5 -> 23.323063 | BK25: =BB25*$BK$5 -> 46.646125 | BL25: =BC25*$BK$5 -> 46.646125 | BM25: =$BM$5 -> 0 | BN25: =BB25*BM25 -> 0 | BO25: =BC25*BM$12 -> 0 | BP25: =$BP$5 -> 0.32 | BQ25: =BB25*$BP25 -> 1492.676 | BR25: =BC25*BP25 -> 1492.676 | BS25: =BB25+BE25+BG25+BI25+BK25+BN25+BQ25 -> 6353.2022 | BT25: =BC25+BF25+BH25+BJ25+BL25+BO25+BR25 -> 6353.2022 | BU25: =BT25/I25 -> 1656.6368
